Workbook
Name PersonNames: 人物主表!$B$3:$B$85

Sheet 人物主表
A1: AI 人物追踪表(2026-09)
A2: 序号 | B2: 姓名 | C2: 外号/昵称 | D2: 英文名 | E2: 机构与职位 | F2: 圈层 | G2: 国别 | H2: 观点立场 | I2: 立场变化 | J2: 代表事件 | K2: 发声渠道 | L2: 关注优先级 | M2: 言论数 | N2: 备注
A3: 1 | B3: 奥特曼 | D3: Sam Altman | E3: OpenAI CEO | F3: AI领军 | G3: 海外 | H3: AGI加速+监管叙事并行 | I3: 2023谨慎叙事→2025《温和奇点》乐观加速 | J3: 2023.11被董事会解雇,5天后回归 | K3: X @sama;博客 samaltman.com | L3: =COUNTIF(言论库!B:B,B3) | M3: 高
A4: 2 | B4: 马斯克 | D4: Elon Musk | E4: xAI创始人;Tesla/SpaceX CEO | F4: AI领军 | G4: 海外 | H4: 风险警告+开源加速并行 | I4: 2015联创OpenAI→2018退出→2024起诉OpenAI | J4: xAI Grok;2024起诉OpenAI违背使命 | K4: X @elonmusk | L4: =COUNTIF(言论库!B:B,B4) | M4: 高
A5: 3 | B5: 阿莫迪 | D5: Dario Amodei | E5: Anthropic CEO | F5: AI领军 | G5: 海外 | H5: 安全派:强AI或2026-2027到来 | I5: 2021带团队离开OpenAI创立Anthropic | J5: 《Machines of Loving Grace》技术乐观路线图 | K5: X @DarioAmodei;官网长文 | L5: =COUNTIF(言论库!B:B,B5) | M5: 高
A6: 4 | B6: 哈萨比斯 | D6: Demis Hassabis | E6: Google DeepMind CEO | F6: AI领军 | G6: 海外 | H6: 谨慎推进:AGI或2030前后 | I6: AlphaGo→AlphaFold→诺奖 | J6: 2024诺贝尔化学奖(AlphaFold) | K6: X @DemisHassabis | L6: =COUNTIF(言论库!B:B,B6) | M6: 高
A7: 5 | B7: 苏茨克维 | D7: Ilya Sutskever | E7: SSI(安全超级智能)创始人 | F7: AI领军 | G7: 海外 | H7: 安全优先:先对齐后加速 | I7: 2023参与罢免奥特曼→2024离开→创立SSI | J7: NeurIPS 2024「预训练时代将终结」 | K7: X @ilyasut | L7: =COUNTIF(言论库!B:B,B7) | M7: 高
A8: 6 | B8: 卡帕西 | D8: Andrej Karpathy | E8: Eureka Labs创始人;前Tesla AI总监 | F8: 技术大神 | G8: 海外 | H8: 教育实用派 | I8: OpenAI创始成员→Tesla→AI教育创业 | J8: 「LLM OS」概念;Eureka Labs | K8: X @karpathy;YouTube/博客 | L8: =COUNTIF(言论库!B:B,B8) | M8: 高
A9: 7 | B9: 杨立昆 | D9: Yann LeCun | E9: Meta首席AI科学家 | F9: 技术大神 | G9: 海外 | H9: 反末日论+开源派 | I9: 2023-2024持续炮轰LLM路线 | J9: 2018图灵奖;公开论战AI末日论 | K9: X @ylecun | L9: =COUNTIF(言论库!B:B,B9) | M9: 高
A10: 8 | B10: 辛顿 | D10: Geoffrey Hinton | E10: 多伦多大学;前Google | F10: 技术大神 | G10: 海外 | H10: 风险警告派:AI或失控 | I10: 2023从Google离职以自由发声 | J10: 2024诺贝尔物理学奖 | K10: X @geoffreyhinton;访谈为主 | L10: =COUNTIF(言论库!B:B,B10) | M10: 高 | N10: 灭绝概率说法多变体,引用前核实
A11: 9 | B11: 本吉奥 | D11: Yoshua Bengio | E11: Mila创始人;蒙特利尔大学 | F11: 技术大神 | G11: 海外 | H11: 安全派:国际监管 | I11: 2018图灵奖→重心转向AI安全 | J11: 2024主导《国际AI安全报告》 | K11: X @YoshuaBengio;Mila官网 | L11: =COUNTIF(言论库!B:B,B11) | M11: 中
A12: 10 | B12: 李飞飞 | D12: Fei-Fei Li | E12: 斯坦福;World Labs创始人 | F12: 学者 | G12: 海外 | H12: 空间智能+务实 | I12: ImageNet→空间智能创业 | J12: ImageNet之母;2024创立World Labs | K12: X @drfeifei | L12: =COUNTIF(言论库!B:B,B12) | M12: 高
A13: 11 | B13: 吴恩达 | D13: Andrew Ng | E13: DeepLearning.AI创始人;斯坦福 | F13: 学者 | G13: 海外 | H13: 实用乐观:AI平民化 | I13: Google Brain→Coursera→AI教育 | J13: 「AI is the new electricity」 | K13: X @AndrewYNg;The Batch 周报 | L13: =COUNTIF(言论库!B:B,B13) | M13: 中
A14: 12 | B14: 黄仁勋 | D14: Jensen Huang | E14: NVIDIA CEO | F14: 芯片硬件 | G14: 海外 | H14: 加速派:算力即生产力 | I14: 图形芯片→AI算力霸主 | J14: CUDA生态;GTC大会 | K14: GTC/COMPUTEX 主题演讲 | L14: =COUNTIF(言论库!B:B,B14) | M14: 高
A15: 13 | B15: 皮查伊 | D15: Sundar Pichai | E15: Google CEO | F15: AI领军 | G15: 海外 | H15: 谨慎推进 | I15: 搜索→AI全线整合 | J15: Gemini全线整合 | K15: X @sundarpichai | L15: =COUNTIF(言论库!B:B,B15) | M15: 中
A16: 14 | B16: 纳德拉 | D16: Satya Nadella | E16: 微软CEO | F16: AI领军 | G16: 海外 | H16: 商业实用派 | I16: 云优先→AI优先 | J16: 百亿美元投OpenAI;Copilot全线 | K16: X @satyanadella | L16: =COUNTIF(言论库!B:B,B16) | M16: 中
A17: 15 | B17: 安德森 | D17: Marc Andreessen | E17: a16z联创 | F17: 投资圈 | G17: 海外 | H17: 技术乐观加速派:反监管 | I17: 互联网投资→AI重注 | J17: 2023.6《Why AI Will Save the World》 | K17: X @pmarca;a16z 博客/播客 | L17: =COUNTIF(言论库!B:B,B17) | M17: 高
A18: 16 | B18: 霍夫曼 | D18: Reid Hoffman | E18: LinkedIn联创;Greylock | F18: 投资圈 | G18: 海外 | H18: 乐观实用:AI放大人 | I18: OpenAI早期董事→持续布道 | J18: 《Impromptu》《Superagency》 | K18: X @reidhoffman;播客/著作 | L18: =COUNTIF(言论库!B:B,B18) | M18: 中
A19: 17 | B19: 科斯拉 | D19: Vinod Khosla | E19: Khosla Ventures创始人 | F19: 投资圈 | G19: 海外 | H19: 乐观但有条件警告 | I19: 2019早期承诺10亿美元投资OpenAI | J19: OpenAI最早机构投资人 | K19: X @vkhosla | L19: =COUNTIF(言论库!B:B,B19) | M19: 中
A20: 18 | B20: 李开复 | D20: Kai-Fu Lee | E20: 零一万物创始人;创新工场董事长 | F20: 投资圈 | G20: 国内 | H20: 实用派:应用层机会 | I20: 微软/谷歌高管→创业孵化→大模型 | J20: 2024「大模型十巨头」论 | K20: X @kaifulee;微博同名 | L20: =COUNTIF(言论库!B:B,B20) | M20: 高
A21: 19 | B21: 梁文锋 | D21: Liang Wenfeng | E21: DeepSeek创始人 | F21: AI领军 | G21: 国内 | H21: 极简务实:开源+低成本 | I21: 幻方量化→DeepSeek | J21: 2025.1 R1发布,引发全球关注 | K21: (极少公开)访谈为主 | L21: =COUNTIF(言论库!B:B,B21) | M21: 高 | N21: 极少发声,素材靠访谈转载
A22: 20 | B22: 杨植麟 | D22: Yang Zhilin | E22: 月之暗面(Kimi)创始人 | F22: AI领军 | G22: 国内 | H22: 技术信仰派 | I22: 清华→卡内基梅隆→创业 | J22: Kimi长上下文 | K22: (极少公开)官方渠道 | L22: =COUNTIF(言论库!B:B,B22) | M22: 高
A23: 21 | B23: 王小川 | D23: Wang Xiaochuan | E23: 百川智能创始人 | F23: AI领军 | G23: 国内 | H23: AGI+生命科学派 | I23: 搜狗CEO→二次创业 | J23: 搜狗出售后转型AGI | K23: 微博@王小川 | L23: =COUNTIF(言论库!B:B,B23) | M23: 中
A24: 22 | B24: 李彦宏 | D24: Robin Li | E24: 百度创始人 | F24: AI领军 | G24: 国内 | H24: 应用务实派 | I24: 搜索→文心一言→萝卜快跑 | J24: 2023.3文心一言国内首发 | K24: (无个人账号)发布会为主 | L24: =COUNTIF(言论库!B:B,B24) | M24: 高 | N24: 闭源言论有争议,引用需上下文
A25: 23 | B25: 周靖人 | D25: Zhou Jingren | E25: 阿里云CTO;通义千问负责人 | F25: AI领军 | G25: 国内 | H25: 开源生态派 | I25: 阿里达摩院→通义千问 | J25: Qwen系列开源全球领跑 | K25: (无个人账号)通义官方 | L25: =COUNTIF(言论库!B:B,B25) | M25: 中
A26: 24 | B26: 朱啸虎 | D26: Zhu Xiaohu | E26: 金沙江创投主管合伙人 | F26: 投资圈 | G26: 国内 | H26: 商业回报务实派 | I26: 2024看空大模型创业→2025拥抱DeepSeek生态 | J26: 「独角兽捕手」 | K26: 微博@朱啸虎;访谈 | L26: =COUNTIF(言论库!B:B,B26) | M26: 中 | N26: 立场反复,注意时间线
A27: 25 | B27: 王兴兴 | D27: Wang Xingxing | E27: 宇树科技创始人 | F27: 机器人 | G27: 国内 | H27: 硬件实干派 | I27: 机器狗→人形机器人 | J27: 2025春晚机器人扭秧歌 | K27: (以采访与官方为主) | L27: =COUNTIF(言论库!B:B,B27) | M27: 高
A28: 26 | B28: 扎克伯格 | D28: Mark Zuckerberg | E28: Meta CEO | F28: 巨头掌门 | G28: 海外 | H28: 开源扩张:Llama 免费开放换生态 | I28: 封闭社交帝国→押注开源大模型 | J28: Llama 3/4 开源;开源闭源路线之争 | K28: Threads @zuck;Meta 官方 | L28: =COUNTIF(言论库!B:B,B28) | M28: 高
A29: 27 | B29: 库克 | D29: Tim Cook | E29: Apple CEO | F29: 巨头掌门 | G29: 海外 | H29: 端侧务实:AI 融入硬件不炫技 | I29: 长期避谈 AI→2024 Apple Intelligence 全线接入 | J29: 2024 WWDC 发布 Apple Intelligence | K29: (极少个人发声)发布会为主 | L29: =COUNTIF(言论库!B:B,B29) | M29: 中
A30: 28 | B30: 贾西 | D30: Andy Jassy | E30: Amazon CEO | F30: 巨头掌门 | G30: 海外 | H30: 基础设施派:AI 是 AWS 的新电力 | I30: 电商运营→All-in AI 云基建 | J30: Bedrock;Trainium 芯片;Nova 模型 | K30: X @ajassy;股东信 | L30: =COUNTIF(言论库!B:B,B30) | M30: 中
A31: 29 | B31: 埃里森 | D31: Larry Ellison | E31: 甲骨文创始人 | F31: 巨头掌门 | G31: 海外 | H31: 激进扩张:AI 数据中心豪赌 | I31: 数据库巨头→AI 云基建狂人 | J31: 与 OpenAI 星门数据中心合作 | K31: 财报电话会/访谈 | L31: =COUNTIF(言论库!B:B,B31) | M31: 中 | N31: 「AI 军备竞赛」类金句频出
A32: 30 | B32: 贝索斯 | D32: Jeff Bezos | E32: 亚马逊创始人 | F32: 巨头掌门 | G32: 海外 | H32: 长期主义:幕后布局 AI 与太空 | I32: CEO 退位→双线押注 | J32: 投资 Perplexity 等 AI 新贵 | K32: X @JeffBezos(偶发) | L32: =COUNTIF(言论库!B:B,B32) | M32: 中
A33: 31 | B33: 苏姿丰 | D33: Lisa Su | E33: AMD CEO | F33: 芯片硬件 | G33: 海外 | H33: 务实攻坚:性能对标英伟达 | I33: 2014 接手濒危 AMD→十年市值百倍 | J33: Instinct MI300 撼动 AI 算力格局 | K33: X @LisaSu;CES/财报会 | L33: =COUNTIF(言论库!B:B,B33) | M33: 高 | N33: 黄仁勋表亲,「苏妈」对比叙事佳
A34: 32 | B34: 丹妮拉 | D34: Daniela Amodei | E34: Anthropic 总裁 | F34: AI领军 | G34: 海外 | H34: 安全派产品化 | I34: OpenAI 副总裁→随兄联创 Anthropic | J34: 与 Dario 共同创立 Anthropic | K34: X @danamodei | L34: =COUNTIF(言论库!B:B,B34) | M34: 中
A35: 33 | B35: 沙泽尔 | D35: Noam Shazeer | E35: Google Gemini 联合负责人 | F35: 技术大神 | G35: 海外 | H35: 技术信仰:规模化至上 | I35: Transformer 作者→创 Character.AI→2024 回归谷歌 | J35: 2017《Attention Is All You Need》合著 | K35: (极少发声)技术访谈 | L35: =COUNTIF(言论库!B:B,B35) | M35: 高 | N35: 「2026 加入 OpenAI」一说待核实
A36: 34 | B36: 沃尔夫 | D36: Thomas Wolf | E36: Hugging Face 联合创始人 | F36: AI领军 | G36: 海外 | H36: 开源生态布道→研究方法批评者 | I36: 纯开源乐观→2025 公开质疑 AI 研究跟风 | J36: Hugging Face 开源生态;2025 批评长文 | K36: X @Thom_Wolf;HF 博客 | L36: =COUNTIF(言论库!B:B,B36) | M36: 中
A37: 35 | B37: 亚历山大·王 | D37: Alexandr Wang | E37: Scale AI 创始人 | F37: AI领军 | G37: 海外 | H37: 数据决定论:高质量数据定 AI 上限 | I37: 19 岁辍学创业→最年轻亿万富翁之一 | J37: 2025 Meta 重金入股 Scale AI | K37: X @alexandr_wang | L37: =COUNTIF(言论库!B:B,B37) | M37: 高
A38: 36 | B38: 珀尔 | D38: Judea Pearl | E38: UCLA 教授;2011 图灵奖 | F38: 学者 | G38: 海外 | H38: 因果革命:现 AI 缺因果推理 | I38: 贝叶斯网络→公开批评深度学习 | J38: 《为什么》;「深度学习=曲线拟合」论战 | K38: 著作/演讲(无社交) | L38: =COUNTIF(言论库!B:B,B38) | M38: 中 | N38: 与深度学习阵营论战素材
A39: 37 | B39: 霍普菲尔德 | D39: John Hopfield | E39: 普林斯顿荣休教授 | F39: 学者 | G39: 海外 | H39: 物理视角看智能 | I39: 1982 Hopfield 网络→42 年后获诺奖 | J39: 2024 诺贝尔物理学奖 | K39: 诺奖演讲/访谈 | L39: =COUNTIF(言论库!B:B,B39) | M39: 中 | N39: 「AI 之根在物理学」科普素材
A40: 38 | B40: 芬恩 | D40: Chelsea Finn | E40: 斯坦福教授 | F40: 学者 | G40: 海外 | H40: 具身智能+元学习 | I40: 纯学术→机器人实训派 | J40: ALOHA 机器人;RT 系列合作 | K40: X @chelseabfinn | L40: =COUNTIF(言论库!B:B,B40) | M40: 中
...

Sheet 言论库
A1: AI 人物言论库(持续追加)
A2: 序号 | B2: 人物姓名 | C2: 圈层 | D2: 言论内容 | E2: 标注 | F2: 出处与场合 | G2: 时间 | H2: 主题标签
A3: 1 | B3: 奥特曼 | C3: AI领军 | D3: 我们正接近一个奇点,但它会是温和的 | E3: 意译(中) | F3: 个人博客《The Gentle Singularity》 | G3: 2025.6 | H3: AGI时间表
A4: 2 | B4: 奥特曼 | C4: AI领军 | D4: AI能力随投入指数提升,成本每年下降约10倍 | E4: 意译(中) | F4: 个人博客《Three Observations》 | G4: 2025.1 | H4: Scaling
A5: 3 | B5: 马斯克 | C5: AI领军 | D5: AI可能比核武器更危险 | E5: 原文(英) | F5: 推特 | G5: 2014.8 | H5: 风险警告
A6: 4 | B6: 马斯克 | C6: AI领军 | D6: xAI的使命是理解宇宙的真实本质 | E6: 意译(中) | F6: xAI发布会 | G6: 2023.7 | H6: 使命
A7: 5 | B7: 阿莫迪 | C7: AI领军 | D7: 治理得当的强AI,能把100年的科学进步压缩到5-10年 | E7: 意译(中) | F7: 博客《Machines of Loving Grace》 | G7: 2024.10 | H7: 乐观路线
A8: 6 | B8: 阿莫迪 | C8: AI领军 | D8: 强大AI可能在2026-2027年间到来,对齐必须先行 | E8: 意译(中) | F8: 媒体访谈 | G8: 2024 | H8: 时间表
A9: 7 | B9: 哈萨比斯 | C9: AI领军 | D9: AGI有望在2030年前后实现 | E9: 意译(中) | F9: 媒体访谈 | G9: 2024 | H9: 时间表
A10: 8 | B10: 哈萨比斯 | C10: AI领军 | D10: AI for Science是AI最大的正向机会 | E10: 意译(中) | F10: 诺贝尔奖相关访谈 | G10: 2024.10 | H10: AI4S
A11: 9 | B11: 苏茨克维 | C11: AI领军 | D11: 预训练时代将终结——数据如同化石燃料 | E11: 意译(中) | F11: NeurIPS演讲 | G11: 2024.12 | H11: 范式转移
A12: 10 | B12: 卡帕西 | C12: 技术大神 | D12: LLM本质上是一种新型操作系统 | E12: 意译(中) | F12: 视频《An Intro to LLMs》 | G12: 2023.11 | H12: 技术认知
A13: 11 | B13: 卡帕西 | C13: 技术大神 | D13: 软件2.0:由数据而非代码定义的程序 | E13: 意译(中) | F13: 博客《Software 2.0》 | G13: 2017 | H13: 范式转移
A14: 12 | B14: 杨立昆 | C14: 技术大神 | D14: 自回归LLM是通往AGI道路上的岔路 | E14: 意译(中) | F14: 社交媒体/访谈(多次) | G14: 2024 | H14: 技术路线
... A33: 31 | B33: 王兴兴 | C33: 机器人 | D33: 人形机器人有望在数年内进入千家万户 | E33: 意译(中) | F33: 媒体采访 | G33: 2025.2 | H33: 机器人时间表
